{
  "nbformat": 4,
  "nbformat_minor": 0,
  "metadata": {
    "colab": {
      "provenance": [],
      "authorship_tag": "ABX9TyOzJD0nEcSxGsJ2hK8dgfvh",
      "include_colab_link": true
    },
    "kernelspec": {
      "name": "python3",
      "display_name": "Python 3"
    },
    "language_info": {
      "name": "python"
    }
  },
  "cells": [
    {
      "cell_type": "markdown",
      "metadata": {
        "id": "view-in-github",
        "colab_type": "text"
      },
      "source": [
        "<a href=\"https://colab.research.google.com/github/FarzanaR11/AI-Horde/blob/main/ali_a01_%7C%7C_VERTEX_AI_powered_healthcare_website_%7C%7C_%242500.ipynb\" target=\"_parent\"><img src=\"https://colab.research.google.com/assets/colab-badge.svg\" alt=\"Open In Colab\"/></a>"
      ]
    },
    {
      "cell_type": "markdown",
      "source": [
        "https://cloud.google.com/vertex-ai/docs/python-sdk/use-vertex-ai-python-sdk?authuser=0\n",
        "\n",
        "https://keep.google.com/#NOTE/1iJITbn7G-a4NyMaJYO4vjXZAm4AImWgyXKTF1zgaHvKwwk-Bnxgpz2RR_FB017o"
      ],
      "metadata": {
        "id": "KR6l9-EcNt-y"
      }
    },
    {
      "cell_type": "code",
      "execution_count": null,
      "metadata": {
        "colab": {
          "base_uri": "https://localhost:8080/",
          "height": 897
        },
        "id": "_fFPTj6UNcVq",
        "outputId": "0f1150f6-0b2d-4cde-dde4-2c0a01b440d1",
        "collapsed": true
      },
      "outputs": [
        {
          "output_type": "stream",
          "name": "stdout",
          "text": [
            "Requirement already satisfied: google-cloud-aiplatform in /usr/local/lib/python3.10/dist-packages (1.70.0)\n",
            "Collecting google-cloud-aiplatform\n",
            "  Downloading google_cloud_aiplatform-1.71.1-py2.py3-none-any.whl.metadata (32 kB)\n",
            "Requirement already satisfied: google-api-core!=2.0.*,!=2.1.*,!=2.2.*,!=2.3.*,!=2.4.*,!=2.5.*,!=2.6.*,!=2.7.*,<3.0.0dev,>=1.34.1 in /usr/local/lib/python3.10/dist-packages (from google-api-core[grpc]!=2.0.*,!=2.1.*,!=2.2.*,!=2.3.*,!=2.4.*,!=2.5.*,!=2.6.*,!=2.7.*,<3.0.0dev,>=1.34.1->google-cloud-aiplatform) (2.19.2)\n",
            "Requirement already satisfied: google-auth<3.0.0dev,>=2.14.1 in /usr/local/lib/python3.10/dist-packages (from google-cloud-aiplatform) (2.27.0)\n",
            "Requirement already satisfied: proto-plus<2.0.0dev,>=1.22.3 in /usr/local/lib/python3.10/dist-packages (from google-cloud-aiplatform) (1.25.0)\n",
            "Requirement already satisfied: protobuf!=4.21.0,!=4.21.1,!=4.21.2,!=4.21.3,!=4.21.4,!=4.21.5,<6.0.0dev,>=3.20.2 in /usr/local/lib/python3.10/dist-packages (from google-cloud-aiplatform) (3.20.3)\n",
            "Requirement already satisfied: packaging>=14.3 in /usr/local/lib/python3.10/dist-packages (from google-cloud-aiplatform) (24.1)\n",
            "Requirement already satisfied: google-cloud-storage<3.0.0dev,>=1.32.0 in /usr/local/lib/python3.10/dist-packages (from google-cloud-aiplatform) (2.8.0)\n",
            "Requirement already satisfied: google-cloud-bigquery!=3.20.0,<4.0.0dev,>=1.15.0 in /usr/local/lib/python3.10/dist-packages (from google-cloud-aiplatform) (3.25.0)\n",
            "Requirement already satisfied: google-cloud-resource-manager<3.0.0dev,>=1.3.3 in /usr/local/lib/python3.10/dist-packages (from google-cloud-aiplatform) (1.13.0)\n",
            "Requirement already satisfied: shapely<3.0.0dev in /usr/local/lib/python3.10/dist-packages (from google-cloud-aiplatform) (2.0.6)\n",
            "Requirement already satisfied: pydantic<3 in /usr/local/lib/python3.10/dist-packages (from google-cloud-aiplatform) (2.9.2)\n",
            "Requirement already satisfied: docstring-parser<1 in /usr/local/lib/python3.10/dist-packages (from google-cloud-aiplatform) (0.16)\n",
            "Requirement already satisfied: googleapis-common-protos<2.0.dev0,>=1.56.2 in /usr/local/lib/python3.10/dist-packages (from google-api-core!=2.0.*,!=2.1.*,!=2.2.*,!=2.3.*,!=2.4.*,!=2.5.*,!=2.6.*,!=2.7.*,<3.0.0dev,>=1.34.1->google-api-core[grpc]!=2.0.*,!=2.1.*,!=2.2.*,!=2.3.*,!=2.4.*,!=2.5.*,!=2.6.*,!=2.7.*,<3.0.0dev,>=1.34.1->google-cloud-aiplatform) (1.65.0)\n",
            "Requirement already satisfied: requests<3.0.0.dev0,>=2.18.0 in /usr/local/lib/python3.10/dist-packages (from google-api-core!=2.0.*,!=2.1.*,!=2.2.*,!=2.3.*,!=2.4.*,!=2.5.*,!=2.6.*,!=2.7.*,<3.0.0dev,>=1.34.1->google-api-core[grpc]!=2.0.*,!=2.1.*,!=2.2.*,!=2.3.*,!=2.4.*,!=2.5.*,!=2.6.*,!=2.7.*,<3.0.0dev,>=1.34.1->google-cloud-aiplatform) (2.32.3)\n",
            "Requirement already satisfied: grpcio<2.0dev,>=1.33.2 in /usr/local/lib/python3.10/dist-packages (from google-api-core[grpc]!=2.0.*,!=2.1.*,!=2.2.*,!=2.3.*,!=2.4.*,!=2.5.*,!=2.6.*,!=2.7.*,<3.0.0dev,>=1.34.1->google-cloud-aiplatform) (1.64.1)\n",
            "Requirement already satisfied: grpcio-status<2.0.dev0,>=1.33.2 in /usr/local/lib/python3.10/dist-packages (from google-api-core[grpc]!=2.0.*,!=2.1.*,!=2.2.*,!=2.3.*,!=2.4.*,!=2.5.*,!=2.6.*,!=2.7.*,<3.0.0dev,>=1.34.1->google-cloud-aiplatform) (1.48.2)\n",
            "Requirement already satisfied: cachetools<6.0,>=2.0.0 in /usr/local/lib/python3.10/dist-packages (from google-auth<3.0.0dev,>=2.14.1->google-cloud-aiplatform) (5.5.0)\n",
            "Requirement already satisfied: pyasn1-modules>=0.2.1 in /usr/local/lib/python3.10/dist-packages (from google-auth<3.0.0dev,>=2.14.1->google-cloud-aiplatform) (0.4.1)\n",
            "Requirement already satisfied: rsa<5,>=3.1.4 in /usr/local/lib/python3.10/dist-packages (from google-auth<3.0.0dev,>=2.14.1->google-cloud-aiplatform) (4.9)\n",
            "Requirement already satisfied: google-cloud-core<3.0.0dev,>=1.6.0 in /usr/local/lib/python3.10/dist-packages (from google-cloud-bigquery!=3.20.0,<4.0.0dev,>=1.15.0->google-cloud-aiplatform) (2.4.1)\n",
            "Requirement already satisfied: google-resumable-media<3.0dev,>=0.6.0 in /usr/local/lib/python3.10/dist-packages (from google-cloud-bigquery!=3.20.0,<4.0.0dev,>=1.15.0->google-cloud-aiplatform) (2.7.2)\n",
            "Requirement already satisfied: python-dateutil<3.0dev,>=2.7.2 in /usr/local/lib/python3.10/dist-packages (from google-cloud-bigquery!=3.20.0,<4.0.0dev,>=1.15.0->google-cloud-aiplatform) (2.8.2)\n",
            "Requirement already satisfied: grpc-google-iam-v1<1.0.0dev,>=0.12.4 in /usr/local/lib/python3.10/dist-packages (from google-cloud-resource-manager<3.0.0dev,>=1.3.3->google-cloud-aiplatform) (0.13.1)\n",
            "Requirement already satisfied: annotated-types>=0.6.0 in /usr/local/lib/python3.10/dist-packages (from pydantic<3->google-cloud-aiplatform) (0.7.0)\n",
            "Requirement already satisfied: pydantic-core==2.23.4 in /usr/local/lib/python3.10/dist-packages (from pydantic<3->google-cloud-aiplatform) (2.23.4)\n",
            "Requirement already satisfied: typing-extensions>=4.6.1 in /usr/local/lib/python3.10/dist-packages (from pydantic<3->google-cloud-aiplatform) (4.12.2)\n",
            "Requirement already satisfied: numpy<3,>=1.14 in /usr/local/lib/python3.10/dist-packages (from shapely<3.0.0dev->google-cloud-aiplatform) (1.26.4)\n",
            "Requirement already satisfied: google-crc32c<2.0dev,>=1.0 in /usr/local/lib/python3.10/dist-packages (from google-resumable-media<3.0dev,>=0.6.0->google-cloud-bigquery!=3.20.0,<4.0.0dev,>=1.15.0->google-cloud-aiplatform) (1.6.0)\n",
            "Requirement already satisfied: pyasn1<0.7.0,>=0.4.6 in /usr/local/lib/python3.10/dist-packages (from pyasn1-modules>=0.2.1->google-auth<3.0.0dev,>=2.14.1->google-cloud-aiplatform) (0.6.1)\n",
            "Requirement already satisfied: six>=1.5 in /usr/local/lib/python3.10/dist-packages (from python-dateutil<3.0dev,>=2.7.2->google-cloud-bigquery!=3.20.0,<4.0.0dev,>=1.15.0->google-cloud-aiplatform) (1.16.0)\n",
            "Requirement already satisfied: charset-normalizer<4,>=2 in /usr/local/lib/python3.10/dist-packages (from requests<3.0.0.dev0,>=2.18.0->google-api-core!=2.0.*,!=2.1.*,!=2.2.*,!=2.3.*,!=2.4.*,!=2.5.*,!=2.6.*,!=2.7.*,<3.0.0dev,>=1.34.1->google-api-core[grpc]!=2.0.*,!=2.1.*,!=2.2.*,!=2.3.*,!=2.4.*,!=2.5.*,!=2.6.*,!=2.7.*,<3.0.0dev,>=1.34.1->google-cloud-aiplatform) (3.4.0)\n",
            "Requirement already satisfied: idna<4,>=2.5 in /usr/local/lib/python3.10/dist-packages (from requests<3.0.0.dev0,>=2.18.0->google-api-core!=2.0.*,!=2.1.*,!=2.2.*,!=2.3.*,!=2.4.*,!=2.5.*,!=2.6.*,!=2.7.*,<3.0.0dev,>=1.34.1->google-api-core[grpc]!=2.0.*,!=2.1.*,!=2.2.*,!=2.3.*,!=2.4.*,!=2.5.*,!=2.6.*,!=2.7.*,<3.0.0dev,>=1.34.1->google-cloud-aiplatform) (3.10)\n",
            "Requirement already satisfied: urllib3<3,>=1.21.1 in /usr/local/lib/python3.10/dist-packages (from requests<3.0.0.dev0,>=2.18.0->google-api-core!=2.0.*,!=2.1.*,!=2.2.*,!=2.3.*,!=2.4.*,!=2.5.*,!=2.6.*,!=2.7.*,<3.0.0dev,>=1.34.1->google-api-core[grpc]!=2.0.*,!=2.1.*,!=2.2.*,!=2.3.*,!=2.4.*,!=2.5.*,!=2.6.*,!=2.7.*,<3.0.0dev,>=1.34.1->google-cloud-aiplatform) (2.2.3)\n",
            "Requirement already satisfied: certifi>=2017.4.17 in /usr/local/lib/python3.10/dist-packages (from requests<3.0.0.dev0,>=2.18.0->google-api-core!=2.0.*,!=2.1.*,!=2.2.*,!=2.3.*,!=2.4.*,!=2.5.*,!=2.6.*,!=2.7.*,<3.0.0dev,>=1.34.1->google-api-core[grpc]!=2.0.*,!=2.1.*,!=2.2.*,!=2.3.*,!=2.4.*,!=2.5.*,!=2.6.*,!=2.7.*,<3.0.0dev,>=1.34.1->google-cloud-aiplatform) (2024.8.30)\n",
            "Downloading google_cloud_aiplatform-1.71.1-py2.py3-none-any.whl (6.2 MB)\n",
            "\u001b[2K   \u001b[90m━━━━━━━━━━━━━━━━━━━━━━━━━━━━━━━━━━━━━━━━\u001b[0m \u001b[32m6.2/6.2 MB\u001b[0m \u001b[31m32.1 MB/s\u001b[0m eta \u001b[36m0:00:00\u001b[0m\n",
            "\u001b[?25hInstalling collected packages: google-cloud-aiplatform\n",
            "  Attempting uninstall: google-cloud-aiplatform\n",
            "    Found existing installation: google-cloud-aiplatform 1.70.0\n",
            "    Uninstalling google-cloud-aiplatform-1.70.0:\n",
            "      Successfully uninstalled google-cloud-aiplatform-1.70.0\n",
            "Successfully installed google-cloud-aiplatform-1.71.1\n"
          ]
        },
        {
          "output_type": "display_data",
          "data": {
            "application/vnd.colab-display-data+json": {
              "pip_warning": {
                "packages": [
                  "google"
                ]
              },
              "id": "b167318c6d2c4c2ca5bcd7eeefceff57"
            }
          },
          "metadata": {}
        }
      ],
      "source": [
        "!pip install --upgrade google-cloud-aiplatform"
      ]
    },
    {
      "cell_type": "code",
      "source": [
        "from google.cloud import aiplatform"
      ],
      "metadata": {
        "id": "95owIPuXNoSa"
      },
      "execution_count": null,
      "outputs": []
    },
    {
      "cell_type": "code",
      "source": [
        "import vertexai.preview"
      ],
      "metadata": {
        "id": "CUO2kO6ANsmy"
      },
      "execution_count": null,
      "outputs": []
    },
    {
      "cell_type": "code",
      "source": [
        "from google.cloud import aiplatform_v1"
      ],
      "metadata": {
        "id": "8kNhYqOcNzup"
      },
      "execution_count": null,
      "outputs": []
    },
    {
      "cell_type": "code",
      "source": [
        "def create_endpoint_sample(\n",
        "    project: str,\n",
        "    display_name: str,\n",
        "    location: str,\n",
        "):\n",
        "    aiplatform.init(project=project, location=location)\n",
        "\n",
        "    endpoint = aiplatform.Endpoint.create(\n",
        "        display_name=display_name,\n",
        "        project=project,\n",
        "        location=location,\n",
        "    )\n",
        "\n",
        "    print(endpoint.display_name)\n",
        "    print(endpoint.resource_name)\n",
        "    return endpoint\n"
      ],
      "metadata": {
        "id": "Ukgj82f6tNMN"
      },
      "execution_count": null,
      "outputs": []
    },
    {
      "cell_type": "code",
      "source": [
        "import vertexai\n",
        "from google.cloud import aiplatform\n",
        "\n",
        "# Initialize Vertex AI with project and location from ALI\n",
        "vertexai.init(project=\"YOUR_PROJECT_ID\", location=\"YOUR_PROJECT_LOCATION\")\n",
        "\n",
        "endpoint = aiplatform.Endpoint.create(\n",
        "  display_name=\"ENDPOINT_NAME\",\n",
        "  dedicated_endpoint_enabled=True,\n",
        ")"
      ],
      "metadata": {
        "colab": {
          "base_uri": "https://localhost:8080/",
          "height": 443
        },
        "id": "4zPKuYOhtRg1",
        "outputId": "f8f6de65-bebe-464b-8dfa-02283335787e",
        "collapsed": true
      },
      "execution_count": null,
      "outputs": [
        {
          "output_type": "error",
          "ename": "ValueError",
          "evalue": "Unsupported region for Vertex AI, select from frozenset({'europe-west12', 'us-west1', 'us-east1', 'southamerica-east1', 'us-west4', 'asia-northeast3', 'southamerica-west1', 'northamerica-northeast2', 'us-central1', 'europe-west1', 'asia-southeast1', 'us-east4', 'europe-north1', 'asia-east2', 'africa-south1', 'europe-southwest1', 'australia-southeast1', 'us-west3', 'northamerica-northeast1', 'me-west1', 'europe-west6', 'europe-central2', 'asia-southeast2', 'europe-west2', 'europe-west4', 'us-east5', 'me-central1', 'europe-west3', 'asia-northeast1', 'europe-west9', 'asia-south1', 'europe-west8', 'asia-east1', 'asia-northeast2', 'australia-southeast2', 'me-central2', 'us-west2', 'us-south1'})",
          "traceback": [
            "\u001b[0;31m---------------------------------------------------------------------------\u001b[0m",
            "\u001b[0;31mValueError\u001b[0m                                Traceback (most recent call last)",
            "\u001b[0;32m<ipython-input-10-480aa74385bf>\u001b[0m in \u001b[0;36m<cell line: 5>\u001b[0;34m()\u001b[0m\n\u001b[1;32m      3\u001b[0m \u001b[0;34m\u001b[0m\u001b[0m\n\u001b[1;32m      4\u001b[0m \u001b[0;31m# Initialize Vertex AI with project and location\u001b[0m\u001b[0;34m\u001b[0m\u001b[0;34m\u001b[0m\u001b[0m\n\u001b[0;32m----> 5\u001b[0;31m \u001b[0mvertexai\u001b[0m\u001b[0;34m.\u001b[0m\u001b[0minit\u001b[0m\u001b[0;34m(\u001b[0m\u001b[0mproject\u001b[0m\u001b[0;34m=\u001b[0m\u001b[0;34m\"YOUR_PROJECT_ID\"\u001b[0m\u001b[0;34m,\u001b[0m \u001b[0mlocation\u001b[0m\u001b[0;34m=\u001b[0m\u001b[0;34m\"YOUR_PROJECT_LOCATION\"\u001b[0m\u001b[0;34m)\u001b[0m\u001b[0;34m\u001b[0m\u001b[0;34m\u001b[0m\u001b[0m\n\u001b[0m\u001b[1;32m      6\u001b[0m \u001b[0;34m\u001b[0m\u001b[0m\n\u001b[1;32m      7\u001b[0m endpoint = aiplatform.Endpoint.create(\n",
            "\u001b[0;32m/usr/local/lib/python3.10/dist-packages/google/cloud/aiplatform/initializer.py\u001b[0m in \u001b[0;36minit\u001b[0;34m(self, project, location, experiment, experiment_description, experiment_tensorboard, staging_bucket, credentials, encryption_spec_key_name, network, service_account, api_endpoint, api_key, api_transport, request_metadata)\u001b[0m\n\u001b[1;32m    239\u001b[0m                 \u001b[0;32mraise\u001b[0m \u001b[0mValueError\u001b[0m\u001b[0;34m(\u001b[0m\u001b[0;34mf\"{api_transport} is not supported with API keys. \"\u001b[0m\u001b[0;34m)\u001b[0m\u001b[0;34m\u001b[0m\u001b[0;34m\u001b[0m\u001b[0m\n\u001b[1;32m    240\u001b[0m         \u001b[0;32mif\u001b[0m \u001b[0mlocation\u001b[0m\u001b[0;34m:\u001b[0m\u001b[0;34m\u001b[0m\u001b[0;34m\u001b[0m\u001b[0m\n\u001b[0;32m--> 241\u001b[0;31m             \u001b[0mutils\u001b[0m\u001b[0;34m.\u001b[0m\u001b[0mvalidate_region\u001b[0m\u001b[0;34m(\u001b[0m\u001b[0mlocation\u001b[0m\u001b[0;34m)\u001b[0m\u001b[0;34m\u001b[0m\u001b[0;34m\u001b[0m\u001b[0m\n\u001b[0m\u001b[1;32m    242\u001b[0m         \u001b[0;32mif\u001b[0m \u001b[0mexperiment_description\u001b[0m \u001b[0;32mand\u001b[0m \u001b[0mexperiment\u001b[0m \u001b[0;32mis\u001b[0m \u001b[0;32mNone\u001b[0m\u001b[0;34m:\u001b[0m\u001b[0;34m\u001b[0m\u001b[0;34m\u001b[0m\u001b[0m\n\u001b[1;32m    243\u001b[0m             raise ValueError(\n",
            "\u001b[0;32m/usr/local/lib/python3.10/dist-packages/google/cloud/aiplatform/utils/__init__.py\u001b[0m in \u001b[0;36mvalidate_region\u001b[0;34m(region)\u001b[0m\n\u001b[1;32m    306\u001b[0m     \u001b[0mregion\u001b[0m \u001b[0;34m=\u001b[0m \u001b[0mregion\u001b[0m\u001b[0;34m.\u001b[0m\u001b[0mlower\u001b[0m\u001b[0;34m(\u001b[0m\u001b[0;34m)\u001b[0m\u001b[0;34m\u001b[0m\u001b[0;34m\u001b[0m\u001b[0m\n\u001b[1;32m    307\u001b[0m     \u001b[0;32mif\u001b[0m \u001b[0mregion\u001b[0m \u001b[0;32mnot\u001b[0m \u001b[0;32min\u001b[0m \u001b[0mconstants\u001b[0m\u001b[0;34m.\u001b[0m\u001b[0mSUPPORTED_REGIONS\u001b[0m\u001b[0;34m:\u001b[0m\u001b[0;34m\u001b[0m\u001b[0;34m\u001b[0m\u001b[0m\n\u001b[0;32m--> 308\u001b[0;31m         raise ValueError(\n\u001b[0m\u001b[1;32m    309\u001b[0m             \u001b[0;34mf\"Unsupported region for Vertex AI, select from {constants.SUPPORTED_REGIONS}\"\u001b[0m\u001b[0;34m\u001b[0m\u001b[0;34m\u001b[0m\u001b[0m\n\u001b[1;32m    310\u001b[0m         )\n",
            "\u001b[0;31mValueError\u001b[0m: Unsupported region for Vertex AI, select from frozenset({'europe-west12', 'us-west1', 'us-east1', 'southamerica-east1', 'us-west4', 'asia-northeast3', 'southamerica-west1', 'northamerica-northeast2', 'us-central1', 'europe-west1', 'asia-southeast1', 'us-east4', 'europe-north1', 'asia-east2', 'africa-south1', 'europe-southwest1', 'australia-southeast1', 'us-west3', 'northamerica-northeast1', 'me-west1', 'europe-west6', 'europe-central2', 'asia-southeast2', 'europe-west2', 'europe-west4', 'us-east5', 'me-central1', 'europe-west3', 'asia-northeast1', 'europe-west9', 'asia-south1', 'europe-west8', 'asia-east1', 'asia-northeast2', 'australia-southeast2', 'me-central2', 'us-west2', 'us-south1'})"
          ]
        }
      ]
    },
    {
      "cell_type": "markdown",
      "source": [
        "https://chatgpt.com/c/672ef6dd-875c-8013-b642-fbdfbffb2184"
      ],
      "metadata": {
        "id": "1VrrscQVgsft"
      }
    },
    {
      "cell_type": "code",
      "source": [
        "!gcloud services enable \\\n",
        "    aiplatform.googleapis.com \\\n",
        "    compute.googleapis.com \\\n",
        "    logging.googleapis.com \\\n",
        "    iam.googleapis.com \\\n",
        "    storage.googleapis.com\n"
      ],
      "metadata": {
        "id": "VEaAkRfGxhKN",
        "colab": {
          "base_uri": "https://localhost:8080/"
        },
        "outputId": "29006f6a-9bb7-46ee-df56-db2e3602d1a2"
      },
      "execution_count": 3,
      "outputs": [
        {
          "output_type": "stream",
          "name": "stdout",
          "text": [
            "\u001b[1;31mERROR:\u001b[0m (gcloud.services.enable) The required property [project] is not currently set.\n",
            "It can be set on a per-command basis by re-running your command with the [--project] flag.\n",
            "\n",
            "You may set it for your current workspace by running:\n",
            "\n",
            "  $ gcloud config set project VALUE\n",
            "\n",
            "or it can be set temporarily by the environment variable [CLOUDSDK_CORE_PROJECT]\n"
          ]
        }
      ]
    },
    {
      "cell_type": "code",
      "source": [
        "import os\n",
        "\n",
        "# Get the Google Cloud project ID from the environment variable.\n",
        "project_id = os.environ.get('GOOGLE_CLOUD_PROJECT')\n",
        "\n",
        "# If the environment variable is not set, try getting it from the gcloud config.\n",
        "if project_id is None:\n",
        "    import subprocess\n",
        "    try:\n",
        "        project_id = subprocess.check_output(\n",
        "            ['gcloud', 'config', 'get-value', 'project'],\n",
        "            universal_newlines=True\n",
        "        ).strip()\n",
        "    except subprocess.CalledProcessError:\n",
        "        project_id = None\n",
        "\n",
        "# If the project ID is still not found, raise an error.\n",
        "if project_id is None:\n",
        "    raise ValueError(\"Could not determine Google Cloud project ID. \"\n",
        "                     \"Please set the GOOGLE_CLOUD_PROJECT environment variable \"\n",
        "                     \"or configure the gcloud CLI.\")\n",
        "\n",
        "# Run the gcloud command with the project ID.\n",
        "!gcloud services enable \\\n",
        "    --project={project_id} \\\n",
        "    aiplatform.googleapis.com \\\n",
        "    compute.googleapis.com \\\n",
        "    logging.googleapis.com \\\n",
        "    iam.googleapis.com \\\n",
        "    storage.googleapis.com"
      ],
      "metadata": {
        "colab": {
          "base_uri": "https://localhost:8080/"
        },
        "id": "qEYE6mf4etzd",
        "outputId": "6026e3b2-e61f-4569-d4c7-97cefd3e89a2"
      },
      "execution_count": 4,
      "outputs": [
        {
          "output_type": "stream",
          "name": "stdout",
          "text": [
            "\u001b[1;31mERROR:\u001b[0m (gcloud.services.enable) The project property is set to the empty string, which is invalid.\n",
            "To set your project, run:\n",
            "\n",
            "  $ gcloud config set project PROJECT_ID\n",
            "\n",
            "or to unset it, run:\n",
            "\n",
            "  $ gcloud config unset project\n"
          ]
        }
      ]
    },
    {
      "cell_type": "code",
      "source": [
        "# Create a shielded VM with no public IP, which complies with HIPAA security standards\n",
        "\n",
        "!gcloud compute instances create hipaa-compliant-vm \\\n",
        "    --zone=us-central1-a \\\n",
        "    --image-family=debian-11 \\\n",
        "    --image-project=debian-cloud \\\n",
        "    --no-address \\\n",
        "    --shielded-secure-boot \\\n",
        "    --shielded-vtpm \\\n",
        "    --metadata-from-file startup-script='./startup-script.sh'"
      ],
      "metadata": {
        "colab": {
          "base_uri": "https://localhost:8080/"
        },
        "id": "qY2PGiQwfCSs",
        "outputId": "847a37ae-169f-461b-c10e-0bfc0a53d693"
      },
      "execution_count": 6,
      "outputs": [
        {
          "output_type": "stream",
          "name": "stdout",
          "text": [
            "\u001b[1;31mERROR:\u001b[0m (gcloud.compute.instances.create) You do not currently have an active account selected.\n",
            "Please run:\n",
            "\n",
            "  $ gcloud auth login\n",
            "\n",
            "to obtain new credentials.\n",
            "\n",
            "If you have already logged in with a different account, run:\n",
            "\n",
            "  $ gcloud config set account ACCOUNT\n",
            "\n",
            "to select an already authenticated account to use.\n"
          ]
        }
      ]
    },
    {
      "cell_type": "code",
      "source": [
        "# Create a HIPAA-compliant bucket\n",
        "!gsutil mb -p YOUR_PROJECT_ID -c STANDARD -l us-central1 gs://your-secure-bucket/\n",
        "\n",
        "# Enable encryption with a customer-managed key (CMK)\n",
        "!gsutil kms encryption -k \"projects/YOUR_PROJECT_ID/locations/global/keyRings/your-key-ring/cryptoKeys/your-key\" gs://your-secure-bucket"
      ],
      "metadata": {
        "colab": {
          "base_uri": "https://localhost:8080/"
        },
        "id": "N3pYlsN_fM6O",
        "outputId": "b1ce7f7c-3aa6-4bf0-e03d-4f6d106a7973"
      },
      "execution_count": 11,
      "outputs": [
        {
          "output_type": "stream",
          "name": "stdout",
          "text": [
            "Creating gs://your-secure-bucket/...\n",
            "You are attempting to access protected data with no configured\n",
            "credentials. Please visit https://cloud.google.com/console#/project\n",
            "and sign up for an account, and then run the \"gcloud auth login\"\n",
            "command to configure gsutil to use these credentials.\n",
            "You are attempting to perform an operation that requires a project id, with none configured. Please re-run gsutil config and make sure to follow the instructions for finding and entering your default project id.\n"
          ]
        }
      ]
    },
    {
      "cell_type": "code",
      "source": [
        "from google.cloud import aiplatform\n",
        "\n",
        "# Initialize Vertex AI\n",
        "aiplatform.init(project='YOUR_PROJECT_ID', location='us-central1')\n",
        "\n",
        "# Upload model to Vertex AI (HIPAA-compliant bucket)\n",
        "model = aiplatform.Model.upload(\n",
        "    display_name=\"hipaa_compliant_model\",\n",
        "    artifact_uri=\"gs://your-secure-bucket/your-model-path/\",\n",
        "    serving_container_image_uri=\"gcr.io/cloud-aiplatform/prediction/tf2-cpu.2-4:latest\"\n",
        ")\n",
        "\n",
        "# Deploy the model to a secure endpoint\n",
        "endpoint = model.deploy(\n",
        "    machine_type=\"n1-standard-4\",  # Select a machine type for your model\n",
        "    traffic_split={\"0\": 100},  # 100% of traffic routed to this model\n",
        "    enable_access_logging=True  # Enable logging of access requests for auditing purposes\n",
        ")\n",
        "\n",
        "print(f\"Model deployed at endpoint: {endpoint.resource_name}\")\n"
      ],
      "metadata": {
        "colab": {
          "base_uri": "https://localhost:8080/",
          "height": 1000
        },
        "collapsed": true,
        "id": "uw-w3kvVh18l",
        "outputId": "6e23caab-8407-4477-d968-1142303adfb2"
      },
      "execution_count": 12,
      "outputs": [
        {
          "output_type": "stream",
          "name": "stderr",
          "text": [
            "ERROR:grpc._plugin_wrapping:AuthMetadataPluginCallback \"<google.auth.transport.grpc.AuthMetadataPlugin object at 0x7c84911048e0>\" raised exception!\n",
            "Traceback (most recent call last):\n",
            "  File \"/usr/local/lib/python3.10/dist-packages/google/auth/compute_engine/credentials.py\", line 128, in refresh\n",
            "    self._retrieve_info(request)\n",
            "  File \"/usr/local/lib/python3.10/dist-packages/google/auth/compute_engine/credentials.py\", line 101, in _retrieve_info\n",
            "    info = _metadata.get_service_account_info(\n",
            "  File \"/usr/local/lib/python3.10/dist-packages/google/auth/compute_engine/_metadata.py\", line 323, in get_service_account_info\n",
            "    return get(request, path, params={\"recursive\": \"true\"})\n",
            "  File \"/usr/local/lib/python3.10/dist-packages/google/auth/compute_engine/_metadata.py\", line 248, in get\n",
            "    raise exceptions.TransportError(\n",
            "google.auth.exceptions.TransportError: (\"Failed to retrieve http://metadata.google.internal/computeMetadata/v1/instance/service-accounts/default/?recursive=true from the Google Compute Engine metadata service. Status: 404 Response:\\nb''\", <google.auth.transport.requests._Response object at 0x7c8490fcf0d0>)\n",
            "\n",
            "The above exception was the direct cause of the following exception:\n",
            "\n",
            "Traceback (most recent call last):\n",
            "  File \"/usr/local/lib/python3.10/dist-packages/grpc/_plugin_wrapping.py\", line 105, in __call__\n",
            "    self._metadata_plugin(\n",
            "  File \"/usr/local/lib/python3.10/dist-packages/google/auth/transport/grpc.py\", line 95, in __call__\n",
            "    callback(self._get_authorization_headers(context), None)\n",
            "  File \"/usr/local/lib/python3.10/dist-packages/google/auth/transport/grpc.py\", line 81, in _get_authorization_headers\n",
            "    self._credentials.before_request(\n",
            "  File \"/usr/local/lib/python3.10/dist-packages/google/auth/credentials.py\", line 228, in before_request\n",
            "    self._blocking_refresh(request)\n",
            "  File \"/usr/local/lib/python3.10/dist-packages/google/auth/credentials.py\", line 191, in _blocking_refresh\n",
            "    self.refresh(request)\n",
            "  File \"/usr/local/lib/python3.10/dist-packages/google/auth/compute_engine/credentials.py\", line 134, in refresh\n",
            "    raise new_exc from caught_exc\n",
            "google.auth.exceptions.RefreshError: (\"Failed to retrieve http://metadata.google.internal/computeMetadata/v1/instance/service-accounts/default/?recursive=true from the Google Compute Engine metadata service. Status: 404 Response:\\nb''\", <google.auth.transport.requests._Response object at 0x7c8490fcf0d0>)\n"
          ]
        },
        {
          "output_type": "error",
          "ename": "ServiceUnavailable",
          "evalue": "503 Getting metadata from plugin failed with error: (\"Failed to retrieve http://metadata.google.internal/computeMetadata/v1/instance/service-accounts/default/?recursive=true from the Google Compute Engine metadata service. Status: 404 Response:\\nb''\", <google.auth.transport.requests._Response object at 0x7c8490fcf0d0>)",
          "traceback": [
            "\u001b[0;31m---------------------------------------------------------------------------\u001b[0m",
            "\u001b[0;31m_InactiveRpcError\u001b[0m                         Traceback (most recent call last)",
            "\u001b[0;32m/usr/local/lib/python3.10/dist-packages/google/api_core/grpc_helpers.py\u001b[0m in \u001b[0;36merror_remapped_callable\u001b[0;34m(*args, **kwargs)\u001b[0m\n\u001b[1;32m     75\u001b[0m         \u001b[0;32mtry\u001b[0m\u001b[0;34m:\u001b[0m\u001b[0;34m\u001b[0m\u001b[0;34m\u001b[0m\u001b[0m\n\u001b[0;32m---> 76\u001b[0;31m             \u001b[0;32mreturn\u001b[0m \u001b[0mcallable_\u001b[0m\u001b[0;34m(\u001b[0m\u001b[0;34m*\u001b[0m\u001b[0margs\u001b[0m\u001b[0;34m,\u001b[0m \u001b[0;34m**\u001b[0m\u001b[0mkwargs\u001b[0m\u001b[0;34m)\u001b[0m\u001b[0;34m\u001b[0m\u001b[0;34m\u001b[0m\u001b[0m\n\u001b[0m\u001b[1;32m     77\u001b[0m         \u001b[0;32mexcept\u001b[0m \u001b[0mgrpc\u001b[0m\u001b[0;34m.\u001b[0m\u001b[0mRpcError\u001b[0m \u001b[0;32mas\u001b[0m \u001b[0mexc\u001b[0m\u001b[0;34m:\u001b[0m\u001b[0;34m\u001b[0m\u001b[0;34m\u001b[0m\u001b[0m\n",
            "\u001b[0;32m/usr/local/lib/python3.10/dist-packages/grpc/_channel.py\u001b[0m in \u001b[0;36m__call__\u001b[0;34m(self, request, timeout, metadata, credentials, wait_for_ready, compression)\u001b[0m\n\u001b[1;32m   1180\u001b[0m         )\n\u001b[0;32m-> 1181\u001b[0;31m         \u001b[0;32mreturn\u001b[0m \u001b[0m_end_unary_response_blocking\u001b[0m\u001b[0;34m(\u001b[0m\u001b[0mstate\u001b[0m\u001b[0;34m,\u001b[0m \u001b[0mcall\u001b[0m\u001b[0;34m,\u001b[0m \u001b[0;32mFalse\u001b[0m\u001b[0;34m,\u001b[0m \u001b[0;32mNone\u001b[0m\u001b[0;34m)\u001b[0m\u001b[0;34m\u001b[0m\u001b[0;34m\u001b[0m\u001b[0m\n\u001b[0m\u001b[1;32m   1182\u001b[0m \u001b[0;34m\u001b[0m\u001b[0m\n",
            "\u001b[0;32m/usr/local/lib/python3.10/dist-packages/grpc/_channel.py\u001b[0m in \u001b[0;36m_end_unary_response_blocking\u001b[0;34m(state, call, with_call, deadline)\u001b[0m\n\u001b[1;32m   1005\u001b[0m     \u001b[0;32melse\u001b[0m\u001b[0;34m:\u001b[0m\u001b[0;34m\u001b[0m\u001b[0;34m\u001b[0m\u001b[0m\n\u001b[0;32m-> 1006\u001b[0;31m         \u001b[0;32mraise\u001b[0m \u001b[0m_InactiveRpcError\u001b[0m\u001b[0;34m(\u001b[0m\u001b[0mstate\u001b[0m\u001b[0;34m)\u001b[0m  \u001b[0;31m# pytype: disable=not-instantiable\u001b[0m\u001b[0;34m\u001b[0m\u001b[0;34m\u001b[0m\u001b[0m\n\u001b[0m\u001b[1;32m   1007\u001b[0m \u001b[0;34m\u001b[0m\u001b[0m\n",
            "\u001b[0;31m_InactiveRpcError\u001b[0m: <_InactiveRpcError of RPC that terminated with:\n\tstatus = StatusCode.UNAVAILABLE\n\tdetails = \"Getting metadata from plugin failed with error: (\"Failed to retrieve http://metadata.google.internal/computeMetadata/v1/instance/service-accounts/default/?recursive=true from the Google Compute Engine metadata service. Status: 404 Response:\\nb''\", <google.auth.transport.requests._Response object at 0x7c8490fcf0d0>)\"\n\tdebug_error_string = \"UNKNOWN:Error received from peer  {created_time:\"2024-11-09T06:06:24.132426696+00:00\", grpc_status:14, grpc_message:\"Getting metadata from plugin failed with error: (\\\"Failed to retrieve http://metadata.google.internal/computeMetadata/v1/instance/service-accounts/default/?recursive=true from the Google Compute Engine metadata service. Status: 404 Response:\\\\nb\\'\\'\\\", <google.auth.transport.requests._Response object at 0x7c8490fcf0d0>)\"}\"\n>",
            "\nThe above exception was the direct cause of the following exception:\n",
            "\u001b[0;31mServiceUnavailable\u001b[0m                        Traceback (most recent call last)",
            "\u001b[0;32m<ipython-input-12-34be4d7280fe>\u001b[0m in \u001b[0;36m<cell line: 7>\u001b[0;34m()\u001b[0m\n\u001b[1;32m      5\u001b[0m \u001b[0;34m\u001b[0m\u001b[0m\n\u001b[1;32m      6\u001b[0m \u001b[0;31m# Upload model to Vertex AI (HIPAA-compliant bucket)\u001b[0m\u001b[0;34m\u001b[0m\u001b[0;34m\u001b[0m\u001b[0m\n\u001b[0;32m----> 7\u001b[0;31m model = aiplatform.Model.upload(\n\u001b[0m\u001b[1;32m      8\u001b[0m     \u001b[0mdisplay_name\u001b[0m\u001b[0;34m=\u001b[0m\u001b[0;34m\"hipaa_compliant_model\"\u001b[0m\u001b[0;34m,\u001b[0m\u001b[0;34m\u001b[0m\u001b[0;34m\u001b[0m\u001b[0m\n\u001b[1;32m      9\u001b[0m     \u001b[0martifact_uri\u001b[0m\u001b[0;34m=\u001b[0m\u001b[0;34m\"gs://your-secure-bucket/your-model-path/\"\u001b[0m\u001b[0;34m,\u001b[0m\u001b[0;34m\u001b[0m\u001b[0;34m\u001b[0m\u001b[0m\n",
            "\u001b[0;32m/usr/local/lib/python3.10/dist-packages/google/cloud/aiplatform/base.py\u001b[0m in \u001b[0;36mwrapper\u001b[0;34m(*args, **kwargs)\u001b[0m\n\u001b[1;32m    861\u001b[0m                 \u001b[0;32mif\u001b[0m \u001b[0mself\u001b[0m\u001b[0;34m:\u001b[0m\u001b[0;34m\u001b[0m\u001b[0;34m\u001b[0m\u001b[0m\n\u001b[1;32m    862\u001b[0m                     \u001b[0mVertexAiResourceNounWithFutureManager\u001b[0m\u001b[0;34m.\u001b[0m\u001b[0mwait\u001b[0m\u001b[0;34m(\u001b[0m\u001b[0mself\u001b[0m\u001b[0;34m)\u001b[0m\u001b[0;34m\u001b[0m\u001b[0;34m\u001b[0m\u001b[0m\n\u001b[0;32m--> 863\u001b[0;31m                 \u001b[0;32mreturn\u001b[0m \u001b[0mmethod\u001b[0m\u001b[0;34m(\u001b[0m\u001b[0;34m*\u001b[0m\u001b[0margs\u001b[0m\u001b[0;34m,\u001b[0m \u001b[0;34m**\u001b[0m\u001b[0mkwargs\u001b[0m\u001b[0;34m)\u001b[0m\u001b[0;34m\u001b[0m\u001b[0;34m\u001b[0m\u001b[0m\n\u001b[0m\u001b[1;32m    864\u001b[0m \u001b[0;34m\u001b[0m\u001b[0m\n\u001b[1;32m    865\u001b[0m             \u001b[0;31m# callbacks to call within the Future (in same Thread)\u001b[0m\u001b[0;34m\u001b[0m\u001b[0;34m\u001b[0m\u001b[0m\n",
            "\u001b[0;32m/usr/local/lib/python3.10/dist-packages/google/cloud/aiplatform/models.py\u001b[0m in \u001b[0;36mupload\u001b[0;34m(cls, serving_container_image_uri, artifact_uri, model_id, parent_model, is_default_version, version_aliases, version_description, serving_container_predict_route, serving_container_health_route, description, serving_container_command, serving_container_args, serving_container_environment_variables, serving_container_ports, serving_container_grpc_ports, local_model, instance_schema_uri, parameters_schema_uri, prediction_schema_uri, explanation_metadata, explanation_parameters, display_name, project, location, credentials, labels, encryption_spec_key_name, staging_bucket, sync, upload_request_timeout, serving_container_deployment_timeout, serving_container_shared_memory_size_mb, serving_container_startup_probe_exec, serving_container_startup_probe_period_seconds, serving_container_startup_probe_timeout_seconds, serving_container_health_probe_exec, serving_container_health_probe_period_seconds, serving_container_health_probe_timeout_seconds)\u001b[0m\n\u001b[1;32m   5032\u001b[0m         )\n\u001b[1;32m   5033\u001b[0m \u001b[0;34m\u001b[0m\u001b[0m\n\u001b[0;32m-> 5034\u001b[0;31m         lro = api_client.upload_model(\n\u001b[0m\u001b[1;32m   5035\u001b[0m             \u001b[0mrequest\u001b[0m\u001b[0;34m=\u001b[0m\u001b[0mrequest\u001b[0m\u001b[0;34m,\u001b[0m\u001b[0;34m\u001b[0m\u001b[0;34m\u001b[0m\u001b[0m\n\u001b[1;32m   5036\u001b[0m             \u001b[0mtimeout\u001b[0m\u001b[0;34m=\u001b[0m\u001b[0mupload_request_timeout\u001b[0m\u001b[0;34m,\u001b[0m\u001b[0;34m\u001b[0m\u001b[0;34m\u001b[0m\u001b[0m\n",
            "\u001b[0;32m/usr/local/lib/python3.10/dist-packages/google/cloud/aiplatform_v1/services/model_service/client.py\u001b[0m in \u001b[0;36mupload_model\u001b[0;34m(self, request, parent, model, retry, timeout, metadata)\u001b[0m\n\u001b[1;32m    921\u001b[0m \u001b[0;34m\u001b[0m\u001b[0m\n\u001b[1;32m    922\u001b[0m         \u001b[0;31m# Send the request.\u001b[0m\u001b[0;34m\u001b[0m\u001b[0;34m\u001b[0m\u001b[0m\n\u001b[0;32m--> 923\u001b[0;31m         response = rpc(\n\u001b[0m\u001b[1;32m    924\u001b[0m             \u001b[0mrequest\u001b[0m\u001b[0;34m,\u001b[0m\u001b[0;34m\u001b[0m\u001b[0;34m\u001b[0m\u001b[0m\n\u001b[1;32m    925\u001b[0m             \u001b[0mretry\u001b[0m\u001b[0;34m=\u001b[0m\u001b[0mretry\u001b[0m\u001b[0;34m,\u001b[0m\u001b[0;34m\u001b[0m\u001b[0;34m\u001b[0m\u001b[0m\n",
            "\u001b[0;32m/usr/local/lib/python3.10/dist-packages/google/api_core/gapic_v1/method.py\u001b[0m in \u001b[0;36m__call__\u001b[0;34m(self, timeout, retry, compression, *args, **kwargs)\u001b[0m\n\u001b[1;32m    129\u001b[0m             \u001b[0mkwargs\u001b[0m\u001b[0;34m[\u001b[0m\u001b[0;34m\"compression\"\u001b[0m\u001b[0;34m]\u001b[0m \u001b[0;34m=\u001b[0m \u001b[0mcompression\u001b[0m\u001b[0;34m\u001b[0m\u001b[0;34m\u001b[0m\u001b[0m\n\u001b[1;32m    130\u001b[0m \u001b[0;34m\u001b[0m\u001b[0m\n\u001b[0;32m--> 131\u001b[0;31m         \u001b[0;32mreturn\u001b[0m \u001b[0mwrapped_func\u001b[0m\u001b[0;34m(\u001b[0m\u001b[0;34m*\u001b[0m\u001b[0margs\u001b[0m\u001b[0;34m,\u001b[0m \u001b[0;34m**\u001b[0m\u001b[0mkwargs\u001b[0m\u001b[0;34m)\u001b[0m\u001b[0;34m\u001b[0m\u001b[0;34m\u001b[0m\u001b[0m\n\u001b[0m\u001b[1;32m    132\u001b[0m \u001b[0;34m\u001b[0m\u001b[0m\n\u001b[1;32m    133\u001b[0m \u001b[0;34m\u001b[0m\u001b[0m\n",
            "\u001b[0;32m/usr/local/lib/python3.10/dist-packages/google/api_core/grpc_helpers.py\u001b[0m in \u001b[0;36merror_remapped_callable\u001b[0;34m(*args, **kwargs)\u001b[0m\n\u001b[1;32m     76\u001b[0m             \u001b[0;32mreturn\u001b[0m \u001b[0mcallable_\u001b[0m\u001b[0;34m(\u001b[0m\u001b[0;34m*\u001b[0m\u001b[0margs\u001b[0m\u001b[0;34m,\u001b[0m \u001b[0;34m**\u001b[0m\u001b[0mkwargs\u001b[0m\u001b[0;34m)\u001b[0m\u001b[0;34m\u001b[0m\u001b[0;34m\u001b[0m\u001b[0m\n\u001b[1;32m     77\u001b[0m         \u001b[0;32mexcept\u001b[0m \u001b[0mgrpc\u001b[0m\u001b[0;34m.\u001b[0m\u001b[0mRpcError\u001b[0m \u001b[0;32mas\u001b[0m \u001b[0mexc\u001b[0m\u001b[0;34m:\u001b[0m\u001b[0;34m\u001b[0m\u001b[0;34m\u001b[0m\u001b[0m\n\u001b[0;32m---> 78\u001b[0;31m             \u001b[0;32mraise\u001b[0m \u001b[0mexceptions\u001b[0m\u001b[0;34m.\u001b[0m\u001b[0mfrom_grpc_error\u001b[0m\u001b[0;34m(\u001b[0m\u001b[0mexc\u001b[0m\u001b[0;34m)\u001b[0m \u001b[0;32mfrom\u001b[0m \u001b[0mexc\u001b[0m\u001b[0;34m\u001b[0m\u001b[0;34m\u001b[0m\u001b[0m\n\u001b[0m\u001b[1;32m     79\u001b[0m \u001b[0;34m\u001b[0m\u001b[0m\n\u001b[1;32m     80\u001b[0m     \u001b[0;32mreturn\u001b[0m \u001b[0merror_remapped_callable\u001b[0m\u001b[0;34m\u001b[0m\u001b[0;34m\u001b[0m\u001b[0m\n",
            "\u001b[0;31mServiceUnavailable\u001b[0m: 503 Getting metadata from plugin failed with error: (\"Failed to retrieve http://metadata.google.internal/computeMetadata/v1/instance/service-accounts/default/?recursive=true from the Google Compute Engine metadata service. Status: 404 Response:\\nb''\", <google.auth.transport.requests._Response object at 0x7c8490fcf0d0>)"
          ]
        }
      ]
    },
    {
      "cell_type": "code",
      "source": [
        "!gcloud projects add-iam-policy-binding YOUR_PROJECT_ID \\\n",
        "    --member=\"user:user@example.com\" \\\n",
        "    --role=\"roles/aiplatform.user\"\n"
      ],
      "metadata": {
        "colab": {
          "base_uri": "https://localhost:8080/"
        },
        "id": "AODa8DJjotzd",
        "outputId": "edba51dd-e2d8-481c-cff1-4028ab216d75"
      },
      "execution_count": 17,
      "outputs": [
        {
          "output_type": "stream",
          "name": "stdout",
          "text": [
            "\u001b[1;31mERROR:\u001b[0m (gcloud.projects.add-iam-policy-binding) You do not currently have an active account selected.\n",
            "Please run:\n",
            "\n",
            "  $ gcloud auth login\n",
            "\n",
            "to obtain new credentials.\n",
            "\n",
            "If you have already logged in with a different account, run:\n",
            "\n",
            "  $ gcloud config set account ACCOUNT\n",
            "\n",
            "to select an already authenticated account to use.\n"
          ]
        }
      ]
    },
    {
      "cell_type": "code",
      "source": [
        "!gcloud logging sinks create hipaa-log-sink \\\n",
        "    storage.googleapis.com/your-secure-bucket \\\n",
        "    --log-filter='resource.type=\"gce_instance\" OR resource.type=\"aiplatform.googleapis.com\"' \\\n",
        "    --include-children \\ # This line was indented incorrectly, causing the error"
      ],
      "metadata": {
        "colab": {
          "base_uri": "https://localhost:8080/"
        },
        "id": "wlWFWp5Io6nF",
        "outputId": "abeb74aa-741e-4267-c231-000dbc10c818"
      },
      "execution_count": 15,
      "outputs": [
        {
          "output_type": "stream",
          "name": "stdout",
          "text": [
            "\u001b[1;31mERROR:\u001b[0m (gcloud.logging.sinks.create) unrecognized arguments:\n",
            "   #\n",
            "  This\n",
            "  line\n",
            "  was\n",
            "  indented\n",
            "  incorrectly,\n",
            "  causing\n",
            "  the\n",
            "  error\n",
            "  To search the help text of gcloud commands, run:\n",
            "  gcloud help -- SEARCH_TERMS\n"
          ]
        }
      ]
    },
    {
      "cell_type": "code",
      "source": [],
      "metadata": {
        "id": "0g_g8ne0pR98"
      },
      "execution_count": null,
      "outputs": []
    }
  ]
}